Workbook

Sheet Lançamentos
A1: Código | B1: Ponto Recebimento | C1: Data de Cadastro | D1: Data de Competência | E1: Modo Pagamento | F1: Histórico | G1: Usuário | H1: Plano de Contas | I1: Entrada | J1: Saída | K1: Categoria DRE
A2: 69697 | B2: Sicredi SNI | C2: 30/06/2026 | D2: 30/06/2026 | E2: PIX | F2: Boleto "55644" do cliente "IVAN LUCAS GALDINO" | G2: system | H2: 02.03.02.01 : Cobrança Bancaria | J2: -0.49 | K2: =IF(H2="02.09 : Outras Saídas", IF(OR(ISNUMBER(SEARCH("CHEQUE COMPE SICREDI", F2)), ISNUMBER(SEARCH("aniversario", F2)), ISNUMBER(SEARCH("churrasco", F2)), ISNUMBER(SEARCH("bolo", F2)), ISNUMBER(SEARCH("SUPERMERCADO", F2))), "6.1 Despesas Administrativas (Pessoal)", IF(OR(ISNUMBER(SEARCH("DLKNET", F2)), ISNUMBER(SEARCH("TESTE", F2))), "6.1 Despesas Administrativas (Gerais)", IFERROR(VLOOKUP(H2, De_Para!A:B, 2, FALSE), "NÃO MAPEADO"))), IFERROR(VLOOKUP(H2, De_Para!A:B, 2, FALSE), "NÃO MAPEADO"))
A3: 69696 | B3: Sicredi SNI | C3: 30/06/2026 | D3: 30/06/2026 | E3: PIX | F3: Boleto "55644" do cliente "IVAN LUCAS GALDINO" | G3: system | H3: 01.01.01 : Mensalidade | I3: 105 | K3: =IF(H3="02.09 : Outras Saídas", IF(OR(ISNUMBER(SEARCH("CHEQUE COMPE SICREDI", F3)), ISNUMBER(SEARCH("aniversario", F3)), ISNUMBER(SEARCH("churrasco", F3)), ISNUMBER(SEARCH("bolo", F3)), ISNUMBER(SEARCH("SUPERMERCADO", F3))), "6.1 Despesas Administrativas (Pessoal)", IF(OR(ISNUMBER(SEARCH("DLKNET", F3)), ISNUMBER(SEARCH("TESTE", F3))), "6.1 Despesas Administrativas (Gerais)", IFERROR(VLOOKUP(H3, De_Para!A:B, 2, FALSE), "NÃO MAPEADO"))), IFERROR(VLOOKUP(H3, De_Para!A:B, 2, FALSE), "NÃO MAPEADO"))
A4: 69695 | B4: Sicredi SNI | C4: 30/06/2026 | D4: 30/06/2026 | E4: PIX | F4: Boleto "67630" do cliente "RAFAEL APARECIDO DE SOUZA" | G4: system | H4: 02.03.02.01 : Cobrança Bancaria | J4: -0.49 | K4: =IF(H4="02.09 : Outras Saídas", IF(OR(ISNUMBER(SEARCH("CHEQUE COMPE SICREDI", F4)), ISNUMBER(SEARCH("aniversario", F4)), ISNUMBER(SEARCH("churrasco", F4)), ISNUMBER(SEARCH("bolo", F4)), ISNUMBER(SEARCH("SUPERMERCADO", F4))), "6.1 Despesas Administrativas (Pessoal)", IF(OR(ISNUMBER(SEARCH("DLKNET", F4)), ISNUMBER(SEARCH("TESTE", F4))), "6.1 Despesas Administrativas (Gerais)", IFERROR(VLOOKUP(H4, De_Para!A:B, 2, FALSE), "NÃO MAPEADO"))), IFERROR(VLOOKUP(H4, De_Para!A:B, 2, FALSE), "NÃO MAPEADO"))
A5: 69694 | B5: Sicredi SNI | C5: 30/06/2026 | D5: 30/06/2026 | E5: PIX | F5: Boleto "67630" do cliente "RAFAEL APARECIDO DE SOUZA" | G5: system | H5: 01.01.01 : Mensalidade | I5: 109.9 | K5: =IF(H5="02.09 : Outras Saídas", IF(OR(ISNUMBER(SEARCH("CHEQUE COMPE SICREDI", F5)), ISNUMBER(SEARCH("aniversario", F5)), ISNUMBER(SEARCH("churrasco", F5)), ISNUMBER(SEARCH("bolo", F5)), ISNUMBER(SEARCH("SUPERMERCADO", F5))), "6.1 Despesas Administrativas (Pessoal)", IF(OR(ISNUMBER(SEARCH("DLKNET", F5)), ISNUMBER(SEARCH("TESTE", F5))), "6.1 Despesas Administrativas (Gerais)", IFERROR(VLOOKUP(H5, De_Para!A:B, 2, FALSE), "NÃO MAPEADO"))), IFERROR(VLOOKUP(H5, De_Para!A:B, 2, FALSE), "NÃO MAPEADO"))
A6: 69693 | B6: Sicredi SNI | C6: 30/06/2026 | D6: 30/06/2026 | E6: PIX | F6: Boleto "67752" do cliente "DARIO OLIVEIRA" | G6: system | H6: 02.03.02.01 : Cobrança Bancaria | J6: -0.49 | K6: =IF(H6="02.09 : Outras Saídas", IF(OR(ISNUMBER(SEARCH("CHEQUE COMPE SICREDI", F6)), ISNUMBER(SEARCH("aniversario", F6)), ISNUMBER(SEARCH("churrasco", F6)), ISNUMBER(SEARCH("bolo", F6)), ISNUMBER(SEARCH("SUPERMERCADO", F6))), "6.1 Despesas Administrativas (Pessoal)", IF(OR(ISNUMBER(SEARCH("DLKNET", F6)), ISNUMBER(SEARCH("TESTE", F6))), "6.1 Despesas Administrativas (Gerais)", IFERROR(VLOOKUP(H6, De_Para!A:B, 2, FALSE), "NÃO MAPEADO"))), IFERROR(VLOOKUP(H6, De_Para!A:B, 2, FALSE), "NÃO MAPEADO"))
A7: 69692 | B7: Sicredi SNI | C7: 30/06/2026 | D7: 30/06/2026 | E7: PIX | F7: Boleto "67752" do cliente "DARIO OLIVEIRA" | G7: system | H7: 01.01.01 : Mensalidade | I7: 104.9 | K7: =IF(H7="02.09 : Outras Saídas", IF(OR(ISNUMBER(SEARCH("CHEQUE COMPE SICREDI", F7)), ISNUMBER(SEARCH("aniversario", F7)), ISNUMBER(SEARCH("churrasco", F7)), ISNUMBER(SEARCH("bolo", F7)), ISNUMBER(SEARCH("SUPERMERCADO", F7))), "6.1 Despesas Administrativas (Pessoal)", IF(OR(ISNUMBER(SEARCH("DLKNET", F7)), ISNUMBER(SEARCH("TESTE", F7))), "6.1 Despesas Administrativas (Gerais)", IFERROR(VLOOKUP(H7, De_Para!A:B, 2, FALSE), "NÃO MAPEADO"))), IFERROR(VLOOKUP(H7, De_Para!A:B, 2, FALSE), "NÃO MAPEADO"))
A8: 69691 | B8: Sicoob | C8: 30/06/2026 | D8: 30/06/2026 | E8: Dinheiro | F8: Boleto "63770" do cliente "JULIA ISABEL FARINCHA" | G8: system | H8: 02.03.02.01 : Cobrança Bancaria | J8: -0.88 | K8: =IF(H8="02.09 : Outras Saídas", IF(OR(ISNUMBER(SEARCH("CHEQUE COMPE SICREDI", F8)), ISNUMBER(SEARCH("aniversario", F8)), ISNUMBER(SEARCH("churrasco", F8)), ISNUMBER(SEARCH("bolo", F8)), ISNUMBER(SEARCH("SUPERMERCADO", F8))), "6.1 Despesas Administrativas (Pessoal)", IF(OR(ISNUMBER(SEARCH("DLKNET", F8)), ISNUMBER(SEARCH("TESTE", F8))), "6.1 Despesas Administrativas (Gerais)", IFERROR(VLOOKUP(H8, De_Para!A:B, 2, FALSE), "NÃO MAPEADO"))), IFERROR(VLOOKUP(H8, De_Para!A:B, 2, FALSE), "NÃO MAPEADO"))
A9: 69690 | B9: Sicoob | C9: 30/06/2026 | D9: 30/06/2026 | E9: Dinheiro | F9: Boleto "63770" do cliente "JULIA ISABEL FARINCHA" | G9: system | H9: 01.01.01 : Mensalidade | I9: 105 | K9: =IF(H9="02.09 : Outras Saídas", IF(OR(ISNUMBER(SEARCH("CHEQUE COMPE SICREDI", F9)), ISNUMBER(SEARCH("aniversario", F9)), ISNUMBER(SEARCH("churrasco", F9)), ISNUMBER(SEARCH("bolo", F9)), ISNUMBER(SEARCH("SUPERMERCADO", F9))), "6.1 Despesas Administrativas (Pessoal)", IF(OR(ISNUMBER(SEARCH("DLKNET", F9)), ISNUMBER(SEARCH("TESTE", F9))), "6.1 Despesas Administrativas (Gerais)", IFERROR(VLOOKUP(H9, De_Para!A:B, 2, FALSE), "NÃO MAPEADO"))), IFERROR(VLOOKUP(H9, De_Para!A:B, 2, FALSE), "NÃO MAPEADO"))
A10: 69689 | B10: Sicoob | C10: 30/06/2026 | D10: 30/06/2026 | E10: Dinheiro | F10: Boleto "59534" do cliente "VILCIANE APARECIDA CAMARGO" | G10: system | H10: 02.03.02.01 : Cobrança Bancaria | J10: -0.88 | K10: =IF(H10="02.09 : Outras Saídas", IF(OR(ISNUMBER(SEARCH("CHEQUE COMPE SICREDI", F10)), ISNUMBER(SEARCH("aniversario", F10)), ISNUMBER(SEARCH("churrasco", F10)), ISNUMBER(SEARCH("bolo", F10)), ISNUMBER(SEARCH("SUPERMERCADO", F10))), "6.1 Despesas Administrativas (Pessoal)", IF(OR(ISNUMBER(SEARCH("DLKNET", F10)), ISNUMBER(SEARCH("TESTE", F10))), "6.1 Despesas Administrativas (Gerais)", IFERROR(VLOOKUP(H10, De_Para!A:B, 2, FALSE), "NÃO MAPEADO"))), IFERROR(VLOOKUP(H10, De_Para!A:B, 2, FALSE), "NÃO MAPEADO"))
A11: 69688 | B11: Sicoob | C11: 30/06/2026 | D11: 30/06/2026 | E11: Dinheiro | F11: Boleto "59534" do cliente "VILCIANE APARECIDA CAMARGO" | G11: system | H11: 01.01.01 : Mensalidade | I11: 105 | K11: =IF(H11="02.09 : Outras Saídas", IF(OR(ISNUMBER(SEARCH("CHEQUE COMPE SICREDI", F11)), ISNUMBER(SEARCH("aniversario", F11)), ISNUMBER(SEARCH("churrasco", F11)), ISNUMBER(SEARCH("bolo", F11)), ISNUMBER(SEARCH("SUPERMERCADO", F11))), "6.1 Despesas Administrativas (Pessoal)", IF(OR(ISNUMBER(SEARCH("DLKNET", F11)), ISNUMBER(SEARCH("TESTE", F11))), "6.1 Despesas Administrativas (Gerais)", IFERROR(VLOOKUP(H11, De_Para!A:B, 2, FALSE), "NÃO MAPEADO"))), IFERROR(VLOOKUP(H11, De_Para!A:B, 2, FALSE), "NÃO MAPEADO"))
A12: 69687 | B12: Sicoob | C12: 30/06/2026 | D12: 30/06/2026 | E12: Dinheiro | F12: Boleto "59513" do cliente "MARCOS SOUZA ESPLUGUES" | G12: system | H12: 02.03.02.01 : Cobrança Bancaria | J12: -0.88 | K12: =IF(H12="02.09 : Outras Saídas", IF(OR(ISNUMBER(SEARCH("CHEQUE COMPE SICREDI", F12)), ISNUMBER(SEARCH("aniversario", F12)), ISNUMBER(SEARCH("churrasco", F12)), ISNUMBER(SEARCH("bolo", F12)), ISNUMBER(SEARCH("SUPERMERCADO", F12))), "6.1 Despesas Administrativas (Pessoal)", IF(OR(ISNUMBER(SEARCH("DLKNET", F12)), ISNUMBER(SEARCH("TESTE", F12))), "6.1 Despesas Administrativas (Gerais)", IFERROR(VLOOKUP(H12, De_Para!A:B, 2, FALSE), "NÃO MAPEADO"))), IFERROR(VLOOKUP(H12, De_Para!A:B, 2, FALSE), "NÃO MAPEADO"))
A13: 69686 | B13: Sicoob | C13: 30/06/2026 | D13: 30/06/2026 | E13: Dinheiro | F13: Boleto "59513" do cliente "MARCOS SOUZA ESPLUGUES" | G13: system | H13: 01.01.01 : Mensalidade | I13: 105 | K13: =IF(H13="02.09 : Outras Saídas", IF(OR(ISNUMBER(SEARCH("CHEQUE COMPE SICREDI", F13)), ISNUMBER(SEARCH("aniversario", F13)), ISNUMBER(SEARCH("churrasco", F13)), ISNUMBER(SEARCH("bolo", F13)), ISNUMBER(SEARCH("SUPERMERCADO", F13))), "6.1 Despesas Administrativas (Pessoal)", IF(OR(ISNUMBER(SEARCH("DLKNET", F13)), ISNUMBER(SEARCH("TESTE", F13))), "6.1 Despesas Administrativas (Gerais)", IFERROR(VLOOKUP(H13, De_Para!A:B, 2, FALSE), "NÃO MAPEADO"))), IFERROR(VLOOKUP(H13, De_Para!A:B, 2, FALSE), "NÃO MAPEADO"))
A14: 69685 | B14: Sicredi SNI | C14: 30/06/2026 | D14: 30/06/2026 | E14: Dinheiro | F14: Boleto "67762" do cliente "JOSE CARLOS DE LIMA" | G14: system | H14: 02.03.02.01 : Cobrança Bancaria | J14: -1.08 | K14: =IF(H14="02.09 : Outras Saídas", IF(OR(ISNUMBER(SEARCH("CHEQUE COMPE SICREDI", F14)), ISNUMBER(SEARCH("aniversario", F14)), ISNUMBER(SEARCH("churrasco", F14)), ISNUMBER(SEARCH("bolo", F14)), ISNUMBER(SEARCH("SUPERMERCADO", F14))), "6.1 Despesas Administrativas (Pessoal)", IF(OR(ISNUMBER(SEARCH("DLKNET", F14)), ISNUMBER(SEARCH("TESTE", F14))), "6.1 Despesas Administrativas (Gerais)", IFERROR(VLOOKUP(H14, De_Para!A:B, 2, FALSE), "NÃO MAPEADO"))), IFERROR(VLOOKUP(H14, De_Para!A:B, 2, FALSE), "NÃO MAPEADO"))
A15: 69684 | B15: Sicredi SNI | C15: 30/06/2026 | D15: 30/06/2026 | E15: Dinheiro | F15: Boleto "67762" do cliente "JOSE CARLOS DE LIMA" | G15: system | H15: 01.01.01 : Mensalidade | I15: 80 | K15: =IF(H15="02.09 : Outras Saídas", IF(OR(ISNUMBER(SEARCH("CHEQUE COMPE SICREDI", F15)), ISNUMBER(SEARCH("aniversario", F15)), ISNUMBER(SEARCH("churrasco", F15)), ISNUMBER(SEARCH("bolo", F15)), ISNUMBER(SEARCH("SUPERMERCADO", F15))), "6.1 Despesas Administrativas (Pessoal)", IF(OR(ISNUMBER(SEARCH("DLKNET", F15)), ISNUMBER(SEARCH("TESTE", F15))), "6.1 Despesas Administrativas (Gerais)", IFERROR(VLOOKUP(H15, De_Para!A:B, 2, FALSE), "NÃO MAPEADO"))), IFERROR(VLOOKUP(H15, De_Para!A:B, 2, FALSE), "NÃO MAPEADO"))
A16: 69683 | B16: Sicredi SNI | C16: 30/06/2026 | D16: 30/06/2026 | E16: Dinheiro | F16: Boleto "67153" do cliente "VANDA APARECIDA CAMARGO" | G16: system | H16: 02.03.02.01 : Cobrança Bancaria | J16: -1.08 | K16: =IF(H16="02.09 : Outras Saídas", IF(OR(ISNUMBER(SEARCH("CHEQUE COMPE SICREDI", F16)), ISNUMBER(SEARCH("aniversario", F16)), ISNUMBER(SEARCH("churrasco", F16)), ISNUMBER(SEARCH("bolo", F16)), ISNUMBER(SEARCH("SUPERMERCADO", F16))), "6.1 Despesas Administrativas (Pessoal)", IF(OR(ISNUMBER(SEARCH("DLKNET", F16)), ISNUMBER(SEARCH("TESTE", F16))), "6.1 Despesas Administrativas (Gerais)", IFERROR(VLOOKUP(H16, De_Para!A:B, 2, FALSE), "NÃO MAPEADO"))), IFERROR(VLOOKUP(H16, De_Para!A:B, 2, FALSE), "NÃO MAPEADO"))
A17: 69682 | B17: Sicredi SNI | C17: 30/06/2026 | D17: 30/06/2026 | E17: Dinheiro | F17: Boleto "67153" do cliente "VANDA APARECIDA CAMARGO" | G17: system | H17: 01.01.01 : Mensalidade | I17: 112.41 | K17: =IF(H17="02.09 : Outras Saídas", IF(OR(ISNUMBER(SEARCH("CHEQUE COMPE SICREDI", F17)), ISNUMBER(SEARCH("aniversario", F17)), ISNUMBER(SEARCH("churrasco", F17)), ISNUMBER(SEARCH("bolo", F17)), ISNUMBER(SEARCH("SUPERMERCADO", F17))), "6.1 Despesas Administrativas (Pessoal)", IF(OR(ISNUMBER(SEARCH("DLKNET", F17)), ISNUMBER(SEARCH("TESTE", F17))), "6.1 Despesas Administrativas (Gerais)", IFERROR(VLOOKUP(H17, De_Para!A:B, 2, FALSE), "NÃO MAPEADO"))), IFERROR(VLOOKUP(H17, De_Para!A:B, 2, FALSE), "NÃO MAPEADO"))
A18: 69681 | B18: Sicoob | C18: 30/06/2026 | D18: 30/06/2026 | E18: Dinheiro | F18: Boleto "66152" do cliente "VALMIR TEODORO LEITE" | G18: system | H18: 02.03.02.01 : Cobrança Bancaria | J18: -0.88 | K18: =IF(H18="02.09 : Outras Saídas", IF(OR(ISNUMBER(SEARCH("CHEQUE COMPE SICREDI", F18)), ISNUMBER(SEARCH("aniversario", F18)), ISNUMBER(SEARCH("churrasco", F18)), ISNUMBER(SEARCH("bolo", F18)), ISNUMBER(SEARCH("SUPERMERCADO", F18))), "6.1 Despesas Administrativas (Pessoal)", IF(OR(ISNUMBER(SEARCH("DLKNET", F18)), ISNUMBER(SEARCH("TESTE", F18))), "6.1 Despesas Administrativas (Gerais)", IFERROR(VLOOKUP(H18, De_Para!A:B, 2, FALSE), "NÃO MAPEADO"))), IFERROR(VLOOKUP(H18, De_Para!A:B, 2, FALSE), "NÃO MAPEADO"))
A19: 69680 | B19: Sicoob | C19: 30/06/2026 | D19: 30/06/2026 | E19: Dinheiro | F19: Boleto "66152" do cliente "VALMIR TEODORO LEITE" | G19: system | H19: 01.03.01 : Mensalidade | I19: 107.45 | K19: =IF(H19="02.09 : Outras Saídas", IF(OR(ISNUMBER(SEARCH("CHEQUE COMPE SICREDI", F19)), ISNUMBER(SEARCH("aniversario", F19)), ISNUMBER(SEARCH("churrasco", F19)), ISNUMBER(SEARCH("bolo", F19)), ISNUMBER(SEARCH("SUPERMERCADO", F19))), "6.1 Despesas Administrativas (Pessoal)", IF(OR(ISNUMBER(SEARCH("DLKNET", F19)), ISNUMBER(SEARCH("TESTE", F19))), "6.1 Despesas Administrativas (Gerais)", IFERROR(VLOOKUP(H19, De_Para!A:B, 2, FALSE), "NÃO MAPEADO"))), IFERROR(VLOOKUP(H19, De_Para!A:B, 2, FALSE), "NÃO MAPEADO"))
A20: 69679 | B20: Sicoob | C20: 30/06/2026 | D20: 30/06/2026 | E20: Dinheiro | F20: Boleto "65405" do cliente "JOSE HUGO BRUNHARI" | G20: system | H20: 02.03.02.01 : Cobrança Bancaria | J20: -0.88 | K20: =IF(H20="02.09 : Outras Saídas", IF(OR(ISNUMBER(SEARCH("CHEQUE COMPE SICREDI", F20)), ISNUMBER(SEARCH("aniversario", F20)), ISNUMBER(SEARCH("churrasco", F20)), ISNUMBER(SEARCH("bolo", F20)), ISNUMBER(SEARCH("SUPERMERCADO", F20))), "6.1 Despesas Administrativas (Pessoal)", IF(OR(ISNUMBER(SEARCH("DLKNET", F20)), ISNUMBER(SEARCH("TESTE", F20))), "6.1 Despesas Administrativas (Gerais)", IFERROR(VLOOKUP(H20, De_Para!A:B, 2, FALSE), "NÃO MAPEADO"))), IFERROR(VLOOKUP(H20, De_Para!A:B, 2, FALSE), "NÃO MAPEADO"))
A21: 69678 | B21: Sicoob | C21: 30/06/2026 | D21: 30/06/2026 | E21: Dinheiro | F21: Boleto "65405" do cliente "JOSE HUGO BRUNHARI" | G21: system | H21: 01.01.01 : Mensalidade | I21: 99.9 | K21: =IF(H21="02.09 : Outras Saídas", IF(OR(ISNUMBER(SEARCH("CHEQUE COMPE SICREDI", F21)), ISNUMBER(SEARCH("aniversario", F21)), ISNUMBER(SEARCH("churrasco", F21)), ISNUMBER(SEARCH("bolo", F21)), ISNUMBER(SEARCH("SUPERMERCADO", F21))), "6.1 Despesas Administrativas (Pessoal)", IF(OR(ISNUMBER(SEARCH("DLKNET", F21)), ISNUMBER(SEARCH("TESTE", F21))), "6.1 Despesas Administrativas (Gerais)", IFERROR(VLOOKUP(H21, De_Para!A:B, 2, FALSE), "NÃO MAPEADO"))), IFERROR(VLOOKUP(H21, De_Para!A:B, 2, FALSE), "NÃO MAPEADO"))
A22: 69677 | B22: Sicoob | C22: 30/06/2026 | D22: 30/06/2026 | E22: Dinheiro | F22: Boleto "64675" do cliente "ADILSON SILVIO AMBROSIO" | G22: system | H22: 02.03.02.01 : Cobrança Bancaria | J22: -0.88 | K22: =IF(H22="02.09 : Outras Saídas", IF(OR(ISNUMBER(SEARCH("CHEQUE COMPE SICREDI", F22)), ISNUMBER(SEARCH("aniversario", F22)), ISNUMBER(SEARCH("churrasco", F22)), ISNUMBER(SEARCH("bolo", F22)), ISNUMBER(SEARCH("SUPERMERCADO", F22))), "6.1 Despesas Administrativas (Pessoal)", IF(OR(ISNUMBER(SEARCH("DLKNET", F22)), ISNUMBER(SEARCH("TESTE", F22))), "6.1 Despesas Administrativas (Gerais)", IFERROR(VLOOKUP(H22, De_Para!A:B, 2, FALSE), "NÃO MAPEADO"))), IFERROR(VLOOKUP(H22, De_Para!A:B, 2, FALSE), "NÃO MAPEADO"))
A23: 69676 | B23: Sicoob | C23: 30/06/2026 | D23: 30/06/2026 | E23: Dinheiro | F23: Boleto "64675" do cliente "ADILSON SILVIO AMBROSIO" | G23: system | H23: 01.01.01 : Mensalidade | I23: 107.51 | K23: =IF(H23="02.09 : Outras Saídas", IF(OR(ISNUMBER(SEARCH("CHEQUE COMPE SICREDI", F23)), ISNUMBER(SEARCH("aniversario", F23)), ISNUMBER(SEARCH("churrasco", F23)), ISNUMBER(SEARCH("bolo", F23)), ISNUMBER(SEARCH("SUPERMERCADO", F23))), "6.1 Despesas Administrativas (Pessoal)", IF(OR(ISNUMBER(SEARCH("DLKNET", F23)), ISNUMBER(SEARCH("TESTE", F23))), "6.1 Despesas Administrativas (Gerais)", IFERROR(VLOOKUP(H23, De_Para!A:B, 2, FALSE), "NÃO MAPEADO"))), IFERROR(VLOOKUP(H23, De_Para!A:B, 2, FALSE), "NÃO MAPEADO"))
A24: 69675 | B24: Sicoob | C24: 30/06/2026 | D24: 30/06/2026 | E24: Dinheiro | F24: Boleto "62711" do cliente "JOSE CANDIDO DA ROSA" | G24: system | H24: 02.03.02.01 : Cobrança Bancaria | J24: -0.88 | K24: =IF(H24="02.09 : Outras Saídas", IF(OR(ISNUMBER(SEARCH("CHEQUE COMPE SICREDI", F24)), ISNUMBER(SEARCH("aniversario", F24)), ISNUMBER(SEARCH("churrasco", F24)), ISNUMBER(SEARCH("bolo", F24)), ISNUMBER(SEARCH("SUPERMERCADO", F24))), "6.1 Despesas Administrativas (Pessoal)", IF(OR(ISNUMBER(SEARCH("DLKNET", F24)), ISNUMBER(SEARCH("TESTE", F24))), "6.1 Despesas Administrativas (Gerais)", IFERROR(VLOOKUP(H24, De_Para!A:B, 2, FALSE), "NÃO MAPEADO"))), IFERROR(VLOOKUP(H24, De_Para!A:B, 2, FALSE), "NÃO MAPEADO"))
A25: 69674 | B25: Sicoob | C25: 30/06/2026 | D25: 30/06/2026 | E25: Dinheiro | F25: Boleto "62711" do cliente "JOSE CANDIDO DA ROSA" | G25: system | H25: 01.01.01 : Mensalidade | I25: 109.9 | K25: =IF(H25="02.09 : Outras Saídas", IF(OR(ISNUMBER(SEARCH("CHEQUE COMPE SICREDI", F25)), ISNUMBER(SEARCH("aniversario", F25)), ISNUMBER(SEARCH("churrasco", F25)), ISNUMBER(SEARCH("bolo", F25)), ISNUMBER(SEARCH("SUPERMERCADO", F25))), "6.1 Despesas Administrativas (Pessoal)", IF(OR(ISNUMBER(SEARCH("DLKNET", F25)), ISNUMBER(SEARCH("TESTE", F25))), "6.1 Despesas Administrativas (Gerais)", IFERROR(VLOOKUP(H25, De_Para!A:B, 2, FALSE), "NÃO MAPEADO"))), IFERROR(VLOOKUP(H25, De_Para!A:B, 2, FALSE), "NÃO MAPEADO"))
A26: 69673 | B26: Sicoob | C26: 30/06/2026 | D26: 30/06/2026 | E26: Dinheiro | F26: Boleto "61154" do cliente "ELAINE TUONO DE OLIVEIRA SANTOS" | G26: system | H26: 02.03.02.01 : Cobrança Bancaria | J26: -0.88 | K26: =IF(H26="02.09 : Outras Saídas", IF(OR(ISNUMBER(SEARCH("CHEQUE COMPE SICREDI", F26)), ISNUMBER(SEARCH("aniversario", F26)), ISNUMBER(SEARCH("churrasco", F26)), ISNUMBER(SEARCH("bolo", F26)), ISNUMBER(SEARCH("SUPERMERCADO", F26))), "6.1 Despesas Administrativas (Pessoal)", IF(OR(ISNUMBER(SEARCH("DLKNET", F26)), ISNUMBER(SEARCH("TESTE", F26))), "6.1 Despesas Administrativas (Gerais)", IFERROR(VLOOKUP(H26, De_Para!A:B, 2, FALSE), "NÃO MAPEADO"))), IFERROR(VLOOKUP(H26, De_Para!A:B, 2, FALSE), "NÃO MAPEADO"))
A27: 69672 | B27: Sicoob | C27: 30/06/2026 | D27: 30/06/2026 | E27: Dinheiro | F27: Boleto "61154" do cliente "ELAINE TUONO DE OLIVEIRA SANTOS" | G27: system | H27: 01.03.01 : Mensalidade | I27: 107.8 | K27: =IF(H27="02.09 : Outras Saídas", IF(OR(ISNUMBER(SEARCH("CHEQUE COMPE SICREDI", F27)), ISNUMBER(SEARCH("aniversario", F27)), ISNUMBER(SEARCH("churrasco", F27)), ISNUMBER(SEARCH("bolo", F27)), ISNUMBER(SEARCH("SUPERMERCADO", F27))), "6.1 Despesas Administrativas (Pessoal)", IF(OR(ISNUMBER(SEARCH("DLKNET", F27)), ISNUMBER(SEARCH("TESTE", F27))), "6.1 Despesas Administrativas (Gerais)", IFERROR(VLOOKUP(H27, De_Para!A:B, 2, FALSE), "NÃO MAPEADO"))), IFERROR(VLOOKUP(H27, De_Para!A:B, 2, FALSE), "NÃO MAPEADO"))
A28: 69671 | B28: Sicoob | C28: 30/06/2026 | D28: 30/06/2026 | E28: Dinheiro | F28: Boleto "55145" do cliente "TIAGO APARECIDO DA SILVA" | G28: system | H28: 02.03.02.01 : Cobrança Bancaria | J28: -0.88 | K28: =IF(H28="02.09 : Outras Saídas", IF(OR(ISNUMBER(SEARCH("CHEQUE COMPE SICREDI", F28)), ISNUMBER(SEARCH("aniversario", F28)), ISNUMBER(SEARCH("churrasco", F28)), ISNUMBER(SEARCH("bolo", F28)), ISNUMBER(SEARCH("SUPERMERCADO", F28))), "6.1 Despesas Administrativas (Pessoal)", IF(OR(ISNUMBER(SEARCH("DLKNET", F28)), ISNUMBER(SEARCH("TESTE", F28))), "6.1 Despesas Administrativas (Gerais)", IFERROR(VLOOKUP(H28, De_Para!A:B, 2, FALSE), "NÃO MAPEADO"))), IFERROR(VLOOKUP(H28, De_Para!A:B, 2, FALSE), "NÃO MAPEADO"))
A29: 69670 | B29: Sicoob | C29: 30/06/2026 | D29: 30/06/2026 | E29: Dinheiro | F29: Boleto "55145" do cliente "TIAGO APARECIDO DA SILVA" | G29: system | H29: 01.01.01 : Mensalidade | I29: 107.27 | K29: =IF(H29="02.09 : Outras Saídas", IF(OR(ISNUMBER(SEARCH("CHEQUE COMPE SICREDI", F29)), ISNUMBER(SEARCH("aniversario", F29)), ISNUMBER(SEARCH("churrasco", F29)), ISNUMBER(SEARCH("bolo", F29)), ISNUMBER(SEARCH("SUPERMERCADO", F29))), "6.1 Despesas Administrativas (Pessoal)", IF(OR(ISNUMBER(SEARCH("DLKNET", F29)), ISNUMBER(SEARCH("TESTE", F29))), "6.1 Despesas Administrativas (Gerais)", IFERROR(VLOOKUP(H29, De_Para!A:B, 2, FALSE), "NÃO MAPEADO"))), IFERROR(VLOOKUP(H29, De_Para!A:B, 2, FALSE), "NÃO MAPEADO"))
A30: 69669 | B30: Sicredi SNI | C30: 30/06/2026 | D30: 30/06/2026 | E30: PIX | F30: Boleto "54988" do cliente "ALEX GOES RIBEIRO" | G30: system | H30: 02.03.02.01 : Cobrança Bancaria | J30: -0.49 | K30: =IF(H30="02.09 : Outras Saídas", IF(OR(ISNUMBER(SEARCH("CHEQUE COMPE SICREDI", F30)), ISNUMBER(SEARCH("aniversario", F30)), ISNUMBER(SEARCH("churrasco", F30)), ISNUMBER(SEARCH("bolo", F30)), ISNUMBER(SEARCH("SUPERMERCADO", F30))), "6.1 Despesas Administrativas (Pessoal)", IF(OR(ISNUMBER(SEARCH("DLKNET", F30)), ISNUMBER(SEARCH("TESTE", F30))), "6.1 Despesas Administrativas (Gerais)", IFERROR(VLOOKUP(H30, De_Para!A:B, 2, FALSE), "NÃO MAPEADO"))), IFERROR(VLOOKUP(H30, De_Para!A:B, 2, FALSE), "NÃO MAPEADO"))
A31: 69668 | B31: Sicredi SNI | C31: 30/06/2026 | D31: 30/06/2026 | E31: PIX | F31: Boleto "54988" do cliente "ALEX GOES RIBEIRO" | G31: system | H31: 01.01.01 : Mensalidade | I31: 107.45 | K31: =IF(H31="02.09 : Outras Saídas", IF(OR(ISNUMBER(SEARCH("CHEQUE COMPE SICREDI", F31)), ISNUMBER(SEARCH("aniversario", F31)), ISNUMBER(SEARCH("churrasco", F31)), ISNUMBER(SEARCH("bolo", F31)), ISNUMBER(SEARCH("SUPERMERCADO", F31))), "6.1 Despesas Administrativas (Pessoal)", IF(OR(ISNUMBER(SEARCH("DLKNET", F31)), ISNUMBER(SEARCH("TESTE", F31))), "6.1 Despesas Administrativas (Gerais)", IFERROR(VLOOKUP(H31, De_Para!A:B, 2, FALSE), "NÃO MAPEADO"))), IFERROR(VLOOKUP(H31, De_Para!A:B, 2, FALSE), "NÃO MAPEADO"))
A32: 69667 | B32: Sicoob | C32: 30/06/2026 | D32: 29/06/2026 | E32: Débito em Conta | F32: TARIFA COBRANÇA | G32: clau | H32: 02.03.03.01 : Tarifas Bancarias | J32: -5.62 | K32: =IF(H32="02.09 : Outras Saídas", IF(OR(ISNUMBER(SEARCH("CHEQUE COMPE SICREDI", F32)), ISNUMBER(SEARCH("aniversario", F32)), ISNUMBER(SEARCH("churrasco", F32)), ISNUMBER(SEARCH("bolo", F32)), ISNUMBER(SEARCH("SUPERMERCADO", F32))), "6.1 Despesas Administrativas (Pessoal)", IF(OR(ISNUMBER(SEARCH("DLKNET", F32)), ISNUMBER(SEARCH("TESTE", F32))), "6.1 Despesas Administrativas (Gerais)", IFERROR(VLOOKUP(H32, De_Para!A:B, 2, FALSE), "NÃO MAPEADO"))), IFERROR(VLOOKUP(H32, De_Para!A:B, 2, FALSE), "NÃO MAPEADO"))
A33: 69666 | B33: Sicoob | C33: 30/06/2026 | D33: 29/06/2026 | E33: PIX | F33: PIX EMITIDO OUTRA IF_x000D_ Pagamento Pix_x000D_ 04.368.898 0001-06 | G33: clau | H33: 02.03.04.07 : ALUGUEL POSTE | J33: -5929.6 | K33: =IF(H33="02.09 : Outras Saídas", IF(OR(ISNUMBER(SEARCH("CHEQUE COMPE SICREDI", F33)), ISNUMBER(SEARCH("aniversario", F33)), ISNUMBER(SEARCH("churrasco", F33)), ISNUMBER(SEARCH("bolo", F33)), ISNUMBER(SEARCH("SUPERMERCADO", F33))), "6.1 Despesas Administrativas (Pessoal)", IF(OR(ISNUMBER(SEARCH("DLKNET", F33)), ISNUMBER(SEARCH("TESTE", F33))), "6.1 Despesas Administrativas (Gerais)", IFERROR(VLOOKUP(H33, De_Para!A:B, 2, FALSE), "NÃO MAPEADO"))), IFERROR(VLOOKUP(H33, De_Para!A:B, 2, FALSE), "NÃO MAPEADO"))
A34: 69665 | B34: Sicredi SNI | C34: 30/06/2026 | D34: 30/06/2026 | E34: Débito em Conta | F34: PIX EMITIDO OUTRA IF_x000D_ Pagamento Pix_x000D_ 04.368.898 0001-06 | G34: clau | H34: 02.03.03.01 : Tarifas Bancarias | J34: -13.52 | K34: =IF(H34="02.09 : Outras Saídas", IF(OR(ISNUMBER(SEARCH("CHEQUE COMPE SICREDI", F34)), ISNUMBER(SEARCH("aniversario", F34)), ISNUMBER(SEARCH("churrasco", F34)), ISNUMBER(SEARCH("bolo", F34)), ISNUMBER(SEARCH("SUPERMERCADO", F34))), "6.1 Despesas Administrativas (Pessoal)", IF(OR(ISNUMBER(SEARCH("DLKNET", F34)), ISNUMBER(SEARCH("TESTE", F34))), "6.1 Despesas Administrativas (Gerais)", IFERROR(VLOOKUP(H34, De_Para!A:B, 2, FALSE), "NÃO MAPEADO"))), IFERROR(VLOOKUP(H34, De_Para!A:B, 2, FALSE), "NÃO MAPEADO"))
A35: 69664 | B35: Sicoob | C35: 30/06/2026 | D35: 30/06/2026 | E35: PIX | F35: PIX EMITIDO OUTRA IF - MESMA TIT._x000D_ Pagamento Pix_x000D_ 10.145.409 0001-50 | G35: clau | H35: 03.02 : TRANSFERENCIA ENTRE CONTAS | J35: -2250 | K35: =IF(H35="02.09 : Outras Saídas", IF(OR(ISNUMBER(SEARCH("CHEQUE COMPE SICREDI", F35)), ISNUMBER(SEARCH("aniversario", F35)), ISNUMBER(SEARCH("churrasco", F35)), ISNUMBER(SEARCH("bolo", F35)), ISNUMBER(SEARCH("SUPERMERCADO", F35))), "6.1 Despesas Administrativas (Pessoal)", IF(OR(ISNUMBER(SEARCH("DLKNET", F35)), ISNUMBER(SEARCH("TESTE", F35))), "6.1 Despesas Administrativas (Gerais)", IFERROR(VLOOKUP(H35, De_Para!A:B, 2, FALSE), "NÃO MAPEADO"))), IFERROR(VLOOKUP(H35, De_Para!A:B, 2, FALSE), "NÃO MAPEADO"))
A36: 69663 | B36: Sicredi SNI | C36: 30/06/2026 | D36: 30/06/2026 | E36: Dinheiro | F36: Boleto "66667" do cliente "LAURINDA DAS DORES IZIDORO" | G36: system | H36: 02.03.02.01 : Cobrança Bancaria | J36: -1.08 | K36: =IF(H36="02.09 : Outras Saídas", IF(OR(ISNUMBER(SEARCH("CHEQUE COMPE SICREDI", F36)), ISNUMBER(SEARCH("aniversario", F36)), ISNUMBER(SEARCH("churrasco", F36)), ISNUMBER(SEARCH("bolo", F36)), ISNUMBER(SEARCH("SUPERMERCADO", F36))), "6.1 Despesas Administrativas (Pessoal)", IF(OR(ISNUMBER(SEARCH("DLKNET", F36)), ISNUMBER(SEARCH("TESTE", F36))), "6.1 Despesas Administrativas (Gerais)", IFERROR(VLOOKUP(H36, De_Para!A:B, 2, FALSE), "NÃO MAPEADO"))), IFERROR(VLOOKUP(H36, De_Para!A:B, 2, FALSE), "NÃO MAPEADO"))
A37: 69662 | B37: Sicredi SNI | C37: 30/06/2026 | D37: 30/06/2026 | E37: Dinheiro | F37: Boleto "66667" do cliente "LAURINDA DAS DORES IZIDORO" | G37: system | H37: 01.01.01 : Mensalidade | I37: 104.9 | K37: =IF(H37="02.09 : Outras Saídas", IF(OR(ISNUMBER(SEARCH("CHEQUE COMPE SICREDI", F37)), ISNUMBER(SEARCH("aniversario", F37)), ISNUMBER(SEARCH("churrasco", F37)), ISNUMBER(SEARCH("bolo", F37)), ISNUMBER(SEARCH("SUPERMERCADO", F37))), "6.1 Despesas Administrativas (Pessoal)", IF(OR(ISNUMBER(SEARCH("DLKNET", F37)), ISNUMBER(SEARCH("TESTE", F37))), "6.1 Despesas Administrativas (Gerais)", IFERROR(VLOOKUP(H37, De_Para!A:B, 2, FALSE), "NÃO MAPEADO"))), IFERROR(VLOOKUP(H37, De_Para!A:B, 2, FALSE), "NÃO MAPEADO"))
A38: 69661 | B38: Sicredi SNI | C38: 30/06/2026 | D38: 30/06/2026 | E38: PIX | F38: Boleto "63097" do cliente "MARIA APARECIDA BREKE BONDARYK" | G38: system | H38: 02.03.02.01 : Cobrança Bancaria | J38: -0.49 | K38: =IF(H38="02.09 : Outras Saídas", IF(OR(ISNUMBER(SEARCH("CHEQUE COMPE SICREDI", F38)), ISNUMBER(SEARCH("aniversario", F38)), ISNUMBER(SEARCH("churrasco", F38)), ISNUMBER(SEARCH("bolo", F38)), ISNUMBER(SEARCH("SUPERMERCADO", F38))), "6.1 Despesas Administrativas (Pessoal)", IF(OR(ISNUMBER(SEARCH("DLKNET", F38)), ISNUMBER(SEARCH("TESTE", F38))), "6.1 Despesas Administrativas (Gerais)", IFERROR(VLOOKUP(H38, De_Para!A:B, 2, FALSE), "NÃO MAPEADO"))), IFERROR(VLOOKUP(H38, De_Para!A:B, 2, FALSE), "NÃO MAPEADO"))
A39: 69660 | B39: Sicredi SNI | C39: 30/06/2026 | D39: 30/06/2026 | E39: PIX | F39: Boleto "63097" do cliente "MARIA APARECIDA BREKE BONDARYK" | G39: system | H39: 01.01.01 : Mensalidade | I39: 104.9 | K39: =IF(H39="02.09 : Outras Saídas", IF(OR(ISNUMBER(SEARCH("CHEQUE COMPE SICREDI", F39)), ISNUMBER(SEARCH("aniversario", F39)), ISNUMBER(SEARCH("churrasco", F39)), ISNUMBER(SEARCH("bolo", F39)), ISNUMBER(SEARCH("SUPERMERCADO", F39))), "6.1 Despesas Administrativas (Pessoal)", IF(OR(ISNUMBER(SEARCH("DLKNET", F39)), ISNUMBER(SEARCH("TESTE", F39))), "6.1 Despesas Administrativas (Gerais)", IFERROR(VLOOKUP(H39, De_Para!A:B, 2, FALSE), "NÃO MAPEADO"))), IFERROR(VLOOKUP(H39, De_Para!A:B, 2, FALSE), "NÃO MAPEADO"))
A40: 69659 | B40: Sicoob | C40: 30/06/2026 | D40: 30/06/2026 | E40: Dinheiro | F40: Boleto "57569" do cliente "MARIA LÚCIA BATISTA DOS REIS" | G40: system | H40: 02.03.02.01 : Cobrança Bancaria | J40: -0.88 | K40: =IF(H40="02.09 : Outras Saídas", IF(OR(ISNUMBER(SEARCH("CHEQUE COMPE SICREDI", F40)), ISNUMBER(SEARCH("aniversario", F40)), ISNUMBER(SEARCH("churrasco", F40)), ISNUMBER(SEARCH("bolo", F40)), ISNUMBER(SEARCH("SUPERMERCADO", F40))), "6.1 Despesas Administrativas (Pessoal)", IF(OR(ISNUMBER(SEARCH("DLKNET", F40)), ISNUMBER(SEARCH("TESTE", F40))), "6.1 Despesas Administrativas (Gerais)", IFERROR(VLOOKUP(H40, De_Para!A:B, 2, FALSE), "NÃO MAPEADO"))), IFERROR(VLOOKUP(H40, De_Para!A:B, 2, FALSE), "NÃO MAPEADO"))
...

Sheet De_Para
A1: Plano de Contas ERP | B1: Categoria DRE
A2: 01.01.01 : Mensalidade | B2: 1.2 Receita de Internet (SVA)
A3: 01.01.02 : Adesão | B3: 1.3 Taxas de Instalação e Adesão
A4: 01.01.03.03 : VALE ALIMENTAÇÃO | B4: 6.1 Despesas Administrativas (Pessoal)
A5: 01.03.01 : Mensalidade | B5: 1.2 Receita de Internet (SVA)
A6: 01.03.02 : Adesão | B6: 1.3 Taxas de Instalação e Adesão
A7: 01.05.02 : Adesão | B7: 1.3 Taxas de Instalação e Adesão
A8: 01.50.02 : Equipamentos | B8: 1.4 Outras Receitas (Equipamentos)
A9: 01.60.01 : Serviço de reparo e manutenção | B9: 1.4 Outras Receitas (Serviços Avulsos)
A10: 01.90 : Outras Entradas | B10: 1.4 Outras Receitas (Diversas)
A11: 02,07 : DÉB.EMPRÉSTIMO | B11: 8.1 Amortização de Empréstimos e Financiamentos
A12: 02.01.02.01 : Folha de Pagamento | B12: 6.1 Despesas Administrativas (Pessoal)
... A48: TRANSF.ENTRE CONTAS : 02.12 | B48: EXCLUÍDO DA DRE

Sheet DRE
A1: DEMONSTRATIVO DE RESULTADOS DO EXERCÍCIO - DRE
A2: Provedor de Internet (ISP) - Relatório Gerencial Dinâmico
A4: Estrutura do Plano de Contas | B4: Valor (R$) | C4: % Rec. Bruta
A5: 1. RECEITA OPERACIONAL BRUTA | B5: =SUM(B6:B10)
A6: 1.2 Receita de Internet (SVA) | B6: =SUMIFS(Lançamentos!I:I, Lançamentos!K:K, "1.2 Receita de Internet (SVA)") | C6: =B6/$B$11
A7: 1.3 Taxas de Instalação e Adesão | B7: =SUMIFS(Lançamentos!I:I, Lançamentos!K:K, "1.3 Taxas de Instalação e Adesão") | C7: =B7/$B$11
A8: 1.4 Outras Receitas (Equipamentos) | B8: =SUMIFS(Lançamentos!I:I, Lançamentos!K:K, "1.4 Outras Receitas (Equipamentos)") | C8: =B8/$B$11
A9: 1.4 Outras Receitas (Serviços Avulsos) | B9: =SUMIFS(Lançamentos!I:I, Lançamentos!K:K, "1.4 Outras Receitas (Serviços Avulsos)") | C9: =B9/$B$11
A10: 1.4 Outras Receitas (Diversas) | B10: =SUMIFS(Lançamentos!I:I, Lançamentos!K:K, "1.4 Outras Receitas (Diversas)") | C10: =B10/$B$11
A11: (=) Total Receita Bruta | B11: =SUM(B6:B10) | C11: =B11/$B$11
A12: 2. (-) DEDUÇÕES E TRIBUTOS | B12: =B14
A13: 2.1 Tributos sobre Serviços (DARF) | B13: =-SUMIFS(Lançamentos!J:J, Lançamentos!K:K, "2.1 Tributos sobre Serviços (DARF)") | C13: =B13/$B$11
A14: (=) Total Deduções | B14: =B13 | C14: =B14/$B$11
A15: 3. (=) RECEITA OPERACIONAL LÍQUIDA (ROL) | B15: =B11-B14 | C15: =B15/$B$11
A16: 4. (-) CUSTOS DOS SERVIÇOS PRESTADOS (CSP) | B16: =B20
A17: 4.1 Links Dedicados / Trânsito IP | B17: =-SUMIFS(Lançamentos!J:J, Lançamentos!K:K, "4.1 Links Dedicados / Trânsito IP") | C17: =B17/$B$11
A18: 4.2 Postes e Aluguel de Infraestrutura | B18: =-SUMIFS(Lançamentos!J:J, Lançamentos!K:K, "4.2 Postes e Aluguel de Infraestrutura") | C18: =B18/$B$11
A19: 4.5 Manutenção de Rede / Licenças Técnicas | B19: =-SUMIFS(Lançamentos!J:J, Lançamentos!K:K, "4.5 Manutenção de Rede / Licenças Técnicas") | C19: =B19/$B$11
A20: (=) Total Custos (CSP) | B20: =SUM(B17:B19) | C20: =B20/$B$11
A21: 5. (=) MARGEM DE CONTRIBUIÇÃO / LUCRO BRUTO | B21: =B15-B20 | C21: =B21/$B$11
A22: 6. (-) DESPESAS OPERACIONAIS (OPEX) | B22: =B30
A23: 6.1 Despesas Administrativas (Pessoal) | B23: =-SUMIFS(Lançamentos!J:J, Lançamentos!K:K, "6.1 Despesas Administrativas (Pessoal)") | C23: =B23/$B$11
A24: 6.1 Despesas Administrativas (Infra) | B24: =-SUMIFS(Lançamentos!J:J, Lançamentos!K:K, "6.1 Despesas Administrativas (Infra)") | C24: =B24/$B$11
A25: 6.1 Despesas Administrativas (Gerais) | B25: =-SUMIFS(Lançamentos!J:J, Lançamentos!K:K, "6.1 Despesas Administrativas (Gerais)") | C25: =B25/$B$11
A26: 6.3 Despesas Financeiras (Taxas Boleto) | B26: =-SUMIFS(Lançamentos!J:J, Lançamentos!K:K, "6.3 Despesas Financeiras (Taxas Boleto)") | C26: =B26/$B$11
A27: 6.3 Despesas Financeiras (Gerais) | B27: =-SUMIFS(Lançamentos!J:J, Lançamentos!K:K, "6.3 Despesas Financeiras (Gerais)") | C27: =B27/$B$11
A28: 6.3 Despesas Financeiras (Encargos) | B28: =-SUMIFS(Lançamentos!J:J, Lançamentos!K:K, "6.3 Despesas Financeiras (Encargos)") | C28: =B28/$B$11
A29: 6.4 Outras Despesas Operacionais | B29: =-SUMIFS(Lançamentos!J:J, Lançamentos!K:K, "6.4 Outras Despesas Operacionais") | C29: =B29/$B$11
A30: (=) Total Despesas (OPEX) | B30: =SUM(B23:B29) | C30: =B30/$B$11
A31: 7. (=) RESULTADO OPERACIONAL (EBITDA) | B31: =B21-B30 | C31: =B31/$B$11
A32: 8. (-) AMORTIZAÇÃO E OUTROS | B32: =B34
A33: 8.1 Amortização de Empréstimos e Financiamentos | B33: =-SUMIFS(Lançamentos!J:J, Lançamentos!K:K, "8.1 Amortização de Empréstimos e Financiamentos") | C33: =B33/$B$11
A34: (=) Total Amortização | B34: =B33 | C34: =B34/$B$11
A35: 9. (=) RESULTADO LÍQUIDO DO EXERCÍCIO | B35: =B31-B34 | C35: =B35/$B$11
